#VRML_SIM R2019a utf8
WorldInfo {
}
Viewpoint {
  orientation -0.1549347829791843 -0.9810401995450333 -0.11642740184266949 1.30730476562405
  position -4.072288423857822 2.2361967014676667 2.2547762293949623
}
TexturedBackground {
}
TexturedBackgroundLight {
}
Floor {
}
DEF MILL_RED_SOLID1 Solid {
  translation 1 0 0
  children [
    DEF GR_OBJECT Group {
      children [
        DEF S_BOX2_DOWN Transform {
          translation -0.5 0.025 0
          children [
            Shape {
              appearance DEF PURPLE PBRAppearance {
                baseColor 0.5333333333333333 0.5411764705882353 0.5215686274509804
              }
              geometry Box {
                size 0.01 0.05 1
              }
            }
          ]
        }
        DEF S_BOX3_DOWN Transform {
          translation -0.5 0.1 0
          children [
            Shape {
              appearance DEF GREEN PBRAppearance {
                baseColor 0.8 0 0
              }
              geometry Box {
                size 0.01 0.1 1
              }
            }
          ]
        }
        DEF S_BOX5_UP Transform {
          translation -0.5 0.9 0
          children [
            Shape {
              appearance USE GREEN
              geometry Box {
                size 0.01 0.1 1
              }
            }
          ]
        }
        DEF S_BOX6_UP Transform {
          translation -0.5 0.975 0
          children [
            Shape {
              appearance USE PURPLE
              geometry Box {
                size 0.01 0.05 1
              }
            }
          ]
        }
        DEF S_BOX7_RIGHT Transform {
          translation -0.5 0.5 0.45
          rotation 1 0 0 1.57
          children [
            Shape {
              appearance USE GREEN
              geometry Box {
                size 0.01 0.1 0.7
              }
            }
          ]
        }
        DEF S_BOX8_LEFT Transform {
          translation -0.5 0.5 -0.45
          rotation 1 0 0 1.57
          children [
            Shape {
              appearance USE GREEN
              geometry Box {
                size 0.01 0.1 0.7
              }
            }
          ]
        }
        DEF S_BOX9_45 Transform {
          translation -0.48 0.5 0
          rotation 1 0 0 0.78
          children [
            Shape {
              appearance USE GREEN
              geometry Box {
                size 0.01 0.07 1.2
              }
            }
          ]
        }
        DEF S_BOX10_45 Transform {
          translation -0.49 0.5 -0.011632203867400322
          rotation 1 0 0 -0.78
          children [
            Shape {
              appearance USE GREEN
              geometry Box {
                size 0.01 0.07 1.2
              }
            }
          ]
        }
        DEF S_BOX_UP Transform {
          translation -0.5 0.975 0
          children [
            Shape {
              appearance USE PURPLE
              geometry Box {
                size 0.01 0.05 1
              }
            }
          ]
        }
      ]
    }
  ]
  name "solid(2)"
  boundingObject USE GR_OBJECT
}
DEF MILL_BLUE_SOLID2 Solid {
  rotation 0 1 0 1.57
  children [
    DEF GR_OBJECT_1 Group {
      children [
        DEF S_BOX2_DOWN Transform {
          translation -0.5 0.025 0
          children [
            Shape {
              appearance DEF S_ORANGE PBRAppearance {
                baseColor 0.7686274509803922 0.6274509803921569 0
              }
              geometry Box {
                size 0.01 0.05 1
              }
            }
          ]
        }
        DEF S_BOX3_DOWN Transform {
          translation -0.5 0.1 0
          children [
            Shape {
              appearance DEF S_BLACK PBRAppearance {
                baseColor 0 0 0
              }
              geometry Box {
                size 0.01 0.1 1
              }
            }
          ]
        }
        DEF S_BOX5_UP Transform {
          translation -0.5 0.9 0
          children [
            Shape {
              appearance USE S_BLACK
              geometry Box {
                size 0.01 0.1 1
              }
            }
          ]
        }
        DEF S_BOX6_UP Transform {
          translation -0.5 0.975 0
          children [
            Shape {
              appearance DEF S_BOX2_BROWN PBRAppearance {
                baseColor 0.9607843137254902 0.4745098039215686 0
                transparency 0.1
              }
              geometry Box {
                size 0.01 0.05 1
              }
            }
          ]
        }
        DEF S_BOX7_RIGHT Transform {
          translation -0.5 0.5 0.45
          rotation 1 0 0 1.57
          children [
            Shape {
              appearance USE S_BLACK
              geometry Box {
                size 0.01 0.1 0.7
              }
            }
          ]
        }
        DEF S_BOX8_LEFT Transform {
          translation -0.5 0.5 -0.45
          rotation 1 0 0 1.57
          children [
            Shape {
              appearance USE S_BLACK
              geometry Box {
                size 0.01 0.1 0.7
              }
            }
          ]
        }
        DEF S_BOX9_45 Transform {
          translation -0.48 0.5 0
          rotation 1 0 0 0.78
          children [
            Shape {
              appearance USE S_BLACK
              geometry Box {
                size 0.01 0.07 1.2
              }
            }
          ]
        }
        DEF S_BOX10_45 Transform {
          translation -0.49 0.5 -0.011632203867400322
          rotation 1 0 0 -0.78
          children [
            Shape {
              appearance USE S_BLACK
              geometry Box {
                size 0.01 0.07 1.2
              }
            }
          ]
        }
      ]
    }
  ]
  name "solid(4)"
  boundingObject USE GR_OBJECT_1
}
DEF MILL_BLUE Solid {
  children [
    USE GR_OBJECT
  ]
}
DEF MILL_RED Solid {
  translation 0 0 -1
  rotation 0 1 0 1.57
  children [
    USE GR_OBJECT_1
  ]
  name "solid(3)"
}
DEF BASE_1 Solid {
  children [
    Shape {
      geometry Box {
        size 1 0.01 1
      }
    }
  ]
  name "solid(1)"
}
DEF BASE_2 Solid {
  translation 0 1 0
  children [
    Shape {
      geometry Box {
        size 1 0.01 1
      }
    }
    HingeJoint {
      jointParameters HingeJointParameters {
      }
      endPoint Solid {
        children [
          Shape {
            appearance PBRAppearance {
              baseColor 0.12549019607843137 0.2901960784313726 0.5294117647058824
            }
            geometry Box {
              size 0.3 0.5 0.3
            }
          }
          HingeJoint {
            jointParameters HingeJointParameters {
            }
            endPoint Solid {
              translation 0 0.5 0
              children [
                Shape {
                  appearance PBRAppearance {
                    baseColor 0 0 0
                  }
                  geometry Cylinder {
                    height 0.5
                    radius 0.05
                  }
                }
                HingeJoint {
                  jointParameters HingeJointParameters {
                  }
                  endPoint Solid {
                    translation 0 0.3 0
                    rotation 1 0 0 1.57
                    children [
                      Group {
                        children [
                          DEF Y_Axis_CYL Transform {
                            children [
                              HingeJoint {
                                jointParameters HingeJointParameters {
                                  axis 0 1 0
                                  anchor 0 0.6 0
                                  staticFriction 0.02
                                }
                                endPoint Solid {
                                  children [
                                    Shape {
                                      appearance PBRAppearance {
                                      }
                                      geometry Cylinder {
                                        height 1
                                        radius 0.05
                                      }
                                    }
                                  ]
                                  physics Physics {
                                  }
                                }
                              }
                            ]
                          }
                          DEF WINDS_1 Transform {
                            translation 0 0.5 0
                          }
                        ]
                      }
                    ]
                  }
                }
              ]
            }
          }
        ]
      }
    }
  ]
  name "solid(5)"
}
